<?xml version="1.0" ?>
<!-- =================================================================================== -->
<!-- |    This document was autogenerated by xacro from robots/ante.urdf.xacro         | -->
<!-- |    EDITING THIS FILE BY HAND IS NOT RECOMMENDED                                 | -->
<!-- =================================================================================== -->
<robot name="ante">
  <!-- create base_link -->
  <link name="base_link"/>
  <!-- fix chassis to base_link, given by parent -->
  <joint name="drivebase_base_link" type="fixed">
    <parent link="base_link"/>
    <child link="chassis_link"/>
    <origin rpy="0 0 0" xyz="0 0 0"/>
  </joint>
  <!-- wheel joints -->
  <joint name="front_left_axle" type="continuous">
    <origin rpy="-1.5707964 0. 1.5707964" xyz="0.111 0.042 -0.012"/>
    <parent link="chassis_link"/>
    <child link="front_left_wheel"/>
    <axis xyz="0. 0. 1."/>
  </joint>
  <joint name="front_right_axle" type="continuous">
    <origin rpy="-1.5707964 0. -1.5707964" xyz="-0.111 0.042 -0.012"/>
    <parent link="chassis_link"/>
    <child link="front_right_wheel"/>
    <axis xyz="0. 0. 1."/>
  </joint>
  <joint name="rear_left_axle" type="continuous">
    <origin rpy="-1.5707964 0. 1.5707964" xyz="0.111 0.182 -0.012"/>
    <parent link="chassis_link"/>
    <child link="rear_left_wheel"/>
    <axis xyz="0. 0. 1."/>
  </joint>
  <joint name="rear_right_axle" type="continuous">
    <origin rpy="-1.5707964 0. -1.5707964" xyz="-0.111 0.182 -0.012"/>
    <parent link="chassis_link"/>
    <child link="rear_right_wheel"/>
    <axis xyz="0. 0. 1."/>
  </joint>
  <link name="chassis_link">
    <visual>
      <origin rpy="0. 0. 0." xyz="0. 0. 0."/>
      <geometry>
        <mesh filename="package://ante_description/meshes/decimated_drivebase.obj" scale="1. 1. 1."/>
      </geometry>
    </visual>
  </link>
  <link name="front_left_wheel">
    <visual>
      <origin rpy="1.5707964 1.5707964 0. " xyz="0. -0. 0.06"/>
      <geometry>
        <mesh filename="package://ante_description/meshes/wheel.obj" scale="1. 1. 1."/>
      </geometry>
    </visual>
    <collision>
      <origin rpy="1.5707964 1.5707964 0. " xyz="0. -0. 0.06"/>
      <geometry>
        <mesh filename="package://ante_description/meshes/wheel.obj" scale="1. 1. 1."/>
      </geometry>
    </collision>
  </link>
  <link name="front_right_wheel">
    <visual>
      <origin rpy="-0.3917964 1.5707964 0. " xyz="-0. -0. 0.06"/>
      <geometry>
        <mesh filename="package://ante_description/meshes/wheel.obj" scale="1. 1. 1."/>
      </geometry>
    </visual>
    <collision>
      <origin rpy="-0.3917964 1.5707964 0. " xyz="-0. -0. 0.06"/>
      <geometry>
        <mesh filename="package://ante_description/meshes/wheel.obj" scale="1. 1. 1."/>
      </geometry>
    </collision>
  </link>
  <link name="rear_left_wheel">
    <visual>
      <origin rpy="-0.3917964 -1.5707964 0. " xyz="0. -0. 0.02"/>
      <geometry>
        <mesh filename="package://ante_description/meshes/wheel.obj" scale="1. 1. 1."/>
      </geometry>
    </visual>
    <collision>
      <origin rpy="-0.3917964 -1.5707964 0. " xyz="0. -0. 0.02"/>
      <geometry>
        <mesh filename="package://ante_description/meshes/wheel.obj" scale="1. 1. 1."/>
      </geometry>
    </collision>
  </link>
  <link name="rear_right_wheel">
    <visual>
      <origin rpy="-0.3917964 1.5707964 0. " xyz="-0. -0. 0.06"/>
      <geometry>
        <mesh filename="package://ante_description/meshes/wheel.obj" scale="1. 1. 1."/>
      </geometry>
    </visual>
    <collision>
      <origin rpy="-0.3917964 1.5707964 0. " xyz="-0. -0. 0.06"/>
      <geometry>
        <mesh filename="package://ante_description/meshes/wheel.obj" scale="1. 1. 1."/>
      </geometry>
    </collision>
  </link>
</robot>
